<sdf version='1.7'>
  <model name='alex'>
    <link name='base_link'>
      <inertial>
        <pose>-0.068 -0 0.034155 0 -0 0</pose>
        <mass>1.09</mass>
        <inertia>
          <ixx>0.00359659</ixx>
          <ixy>-6.81511e-19</ixy>
          <ixz>8.67362e-19</ixz>
          <iyy>0.0060024</iyy>
          <iyz>2.83444e-34</iyz>
          <izz>0.00712878</izz>
        </inertia>
      </inertial>
      <collision name='base_link_fixed_joint_lump__chassis_collision'>
        <pose>-0.068 0 0.0095 1.5708 0 -1.5708</pose>
        <geometry>
          <box>
            <size>0.192 0.059 0.276</size>
          </box>
        </geometry>
        <surface>
          <contact>
            <ode>
              <kp>10000</kp>
              <kd>10000</kd>
            </ode>
          </contact>
          <friction>
            <ode>
              <mu>1</mu>
              <mu2>1</mu2>
            </ode>
          </friction>
        </surface>
      </collision>
      <collision name='base_link_fixed_joint_lump__ep_collision_1'>
        <pose>-0.068 0 0.047975 1.5708 0 -1.5708</pose>
        <geometry>
          <box>
            <size>0.1015 0.018 0.134</size>
          </box>
        </geometry>
        <surface>
          <contact>
            <ode>
              <kp>10000</kp>
              <kd>10000</kd>
            </ode>
          </contact>
          <friction>
            <ode>
              <mu>1</mu>
              <mu2>1</mu2>
            </ode>
          </friction>
        </surface>
      </collision>
      <collision name='base_link_fixed_joint_lump__pt4_collision_2'>
        <pose>-0.068 0 0.073475 1.5708 0 -1.5708</pose>
        <geometry>
          <box>
            <size>0.0995 0.034 0.132</size>
          </box>
        </geometry>
        <surface>
          <contact>
            <ode>
              <kp>10000</kp>
              <kd>10000</kd>
            </ode>
          </contact>
          <friction>
            <ode>
              <mu>1</mu>
              <mu2>1</mu2>
            </ode>
          </friction>
        </surface>
      </collision>
      <visual name='base_link_fixed_joint_lump__chassis_visual'>
        <pose>-0.068 0 0.056475 1.5708 0 -1.5708</pose>
        <geometry>
          <mesh>
            <scale>1 1 1</scale>
            <uri>model://alex/meshes/chassis_asm_dessimate.dae</uri>
          </mesh>
        </geometry>
      </visual>
      <visual name='base_link_fixed_joint_lump__ep_visual_1'>
        <pose>-0.068 0 0.056475 1.5708 0 -1.5708</pose>
        <geometry>
          <box>
            <size>0.1015 0.018 0.134</size>
          </box>
        </geometry>
      </visual>
      <visual name='base_link_fixed_joint_lump__imu_link_visual_2'>
        <pose>-0.068 0 0.047975 1.5708 0 -1.5708</pose>
        <geometry>
          <box>
            <size>0.001 0.001 0.001</size>
          </box>
        </geometry>
      </visual>
      <visual name='base_link_fixed_joint_lump__pt4_visual_3'>
        <pose>-0.068 0 0.056475 1.5708 0 -1.5708</pose>
        <geometry>
          <box>
            <size>0.0995 0.034 0.132</size>
          </box>
        </geometry>
      </visual>
      <velocity_decay/>
      <velocity_decay/>
      <velocity_decay/>
      <gravity>1</gravity>
      <sensor name='imu_sensor' type='imu'>
        <always_on>1</always_on>
        <update_rate>100</update_rate>
        <visualize>1</visualize>
        <topic>__default_topic__</topic>
        <plugin name='imu_plugin' filename='libgazebo_ros_imu_sensor.so'>
          <topicName>imu</topicName>
          <bodyName>imu_link</bodyName>
          <updateRateHZ>10.0</updateRateHZ>
          <gaussianNoise>0.0</gaussianNoise>
          <xyzOffset>0 0 0</xyzOffset>
          <rpyOffset>0 0 0</rpyOffset>
          <frameName>imu_link</frameName>
          <initialOrientationAsReference>0</initialOrientationAsReference>
        </plugin>
        <pose>-0.068 0 0.047975 1.5708 0 -1.5708</pose>
      </sensor>
      <gravity>1</gravity>
      <velocity_decay/>
    </link>
    <joint name='baselink_castor_joint' type='revolute'>
      <pose relative_to='base_link'>-0.148 0 -0.00204 0 -0 0</pose>
      <parent>base_link</parent>
      <child>castor</child>
      <axis>
        <xyz>0 0 1</xyz>
        <limit>
          <lower>-1e+16</lower>
          <upper>1e+16</upper>
        </limit>
        <dynamics>
          <spring_reference>0</spring_reference>
          <spring_stiffness>0</spring_stiffness>
        </dynamics>
      </axis>
    </joint>
    <link name='castor'>
      <pose relative_to='baselink_castor_joint'>0 0 0 0 -0 0</pose>
      <inertial>
        <pose>0 0 -0.0125 0 -0 0</pose>
        <mass>0.001</mass>
        <inertia>
          <ixx>1.17693e-07</ixx>
          <ixy>0</ixy>
          <ixz>0</ixz>
          <iyy>1.17693e-07</iyy>
          <iyz>0</iyz>
          <izz>1.3122e-07</izz>
        </inertia>
      </inertial>
      <collision name='castor_collision'>
        <pose>0 0 -0.0125 0 -0 0</pose>
        <geometry>
          <cylinder>
            <length>0.025</length>
            <radius>0.0162</radius>
          </cylinder>
        </geometry>
        <surface>
          <contact>
            <ode>
              <kp>10000</kp>
              <kd>10000</kd>
            </ode>
          </contact>
          <friction>
            <ode>
              <mu>10</mu>
              <mu2>10</mu2>
            </ode>
          </friction>
        </surface>
      </collision>
      <visual name='castor_visual'>
        <pose>0.08 0 0.058515 1.5708 0 -1.5708</pose>
        <geometry>
          <mesh>
            <scale>1 1 1</scale>
            <uri>model://alex/meshes/castor_asm_3_dessimate.dae</uri>
          </mesh>
        </geometry>
      </visual>
      <gravity>1</gravity>
      <velocity_decay/>
    </link>
    <joint name='castor_castorwheel_joint' type='revolute'>
      <pose relative_to='castor'>-0.016 0 -0.0205 -1.5708 0 0</pose>
      <parent>castor</parent>
      <child>castor_wheel</child>
      <axis>
        <xyz>0 0 1</xyz>
        <limit>
          <lower>-1e+16</lower>
          <upper>1e+16</upper>
        </limit>
        <dynamics>
          <spring_reference>0</spring_reference>
          <spring_stiffness>0</spring_stiffness>
        </dynamics>
      </axis>
    </joint>
    <link name='castor_wheel'>
      <pose relative_to='castor_castorwheel_joint'>0 0 0 0 -0 0</pose>
      <inertial>
        <pose>0 0 0 0 -0 0</pose>
        <mass>0.001</mass>
        <inertia>
          <ixx>5.65833e-08</ixx>
          <ixy>0</ixy>
          <ixz>0</ixz>
          <iyy>5.65833e-08</iyy>
          <iyz>0</iyz>
          <izz>7.8125e-08</izz>
        </inertia>
      </inertial>
      <collision name='castor_wheel_collision'>
        <pose>0 0 0 0 -0 0</pose>
        <geometry>
          <cylinder>
            <length>0.0145</length>
            <radius>0.0125</radius>
          </cylinder>
        </geometry>
        <surface>
          <contact>
            <ode>
              <kp>1000</kp>
              <kd>1000</kd>
            </ode>
          </contact>
          <friction>
            <ode>
              <mu>10</mu>
              <mu2>10</mu2>
            </ode>
          </friction>
        </surface>
      </collision>
      <gravity>1</gravity>
      <velocity_decay/>
    </link>
    <joint name='pan_mechanism_joint' type='revolute'>
      <pose relative_to='base_link'>0.074268 0 0.019194 -1.5708 -0 -3.14159</pose>
      <parent>base_link</parent>
      <child>pan_mechanism</child>
      <axis>
        <xyz>0 1 0</xyz>
        <limit>
          <lower>-1.5708</lower>
          <upper>1.5708</upper>
          <effort>1</effort>
          <velocity>1.74533</velocity>
        </limit>
        <dynamics>
          <spring_reference>0</spring_reference>
          <spring_stiffness>0</spring_stiffness>
        </dynamics>
      </axis>
    </joint>
    <link name='pan_mechanism'>
      <pose relative_to='pan_mechanism_joint'>0 0 0 0 -0 0</pose>
      <inertial>
        <pose>0 0 0 0 -0 0</pose>
        <mass>0.005</mass>
        <inertia>
          <ixx>1.5776e-06</ixx>
          <ixy>0</ixy>
          <ixz>0</ixz>
          <iyy>1.06667e-06</iyy>
          <iyz>0</iyz>
          <izz>7.24271e-07</izz>
        </inertia>
      </inertial>
      <collision name='pan_mechanism_collision'>
        <pose>0 0 0 0 -0 0</pose>
        <geometry>
          <box>
            <size>0.016 0.0385 0.048</size>
          </box>
        </geometry>
        <surface>
          <contact>
            <ode>
              <kp>10000</kp>
              <kd>10000</kd>
            </ode>
          </contact>
          <friction>
            <ode>
              <mu>1</mu>
              <mu2>1</mu2>
            </ode>
          </friction>
        </surface>
      </collision>
      <visual name='pan_mechanism_visual'>
        <pose>0 0 0 0 -0 0</pose>
        <geometry>
          <mesh>
            <scale>1 1 1</scale>
            <uri>model://alex/meshes/pan_asm_2_dessimate_2.dae</uri>
          </mesh>
        </geometry>
      </visual>
      <gravity>1</gravity>
      <velocity_decay/>
    </link>
    <joint name='tilt_mechanism_joint' type='revolute'>
      <pose relative_to='pan_mechanism'>0 -0.04825 -0.000526 1.5708 -0 3.14159</pose>
      <parent>pan_mechanism</parent>
      <child>tilt_mechanism</child>
      <axis>
        <xyz>0 1 0</xyz>
        <limit>
          <lower>-1.5708</lower>
          <upper>1.5708</upper>
          <effort>1</effort>
          <velocity>1.74533</velocity>
        </limit>
        <dynamics>
          <spring_reference>0</spring_reference>
          <spring_stiffness>0</spring_stiffness>
        </dynamics>
      </axis>
    </joint>
    <link name='tilt_mechanism'>
      <pose relative_to='tilt_mechanism_joint'>0 0 0 0 -0 0</pose>
      <inertial>
        <pose>0.00725 0.000175 0 0 -0 0</pose>
        <mass>0.01</mass>
        <inertia>
          <ixx>2.04796e-06</ixx>
          <ixy>-1.26875e-08</ixy>
          <ixz>0</ixz>
          <iyy>1.89138e-06</iyy>
          <iyz>0</iyz>
          <izz>1.54929e-06</izz>
        </inertia>
      </inertial>
      <collision name='tilt_mechanism_collision'>
        <pose>0 0 0 0 -0 0</pose>
        <geometry>
          <box>
            <size>0.016 0.0385 0.048</size>
          </box>
        </geometry>
        <surface>
          <contact>
            <ode>
              <kp>10000</kp>
              <kd>10000</kd>
            </ode>
          </contact>
          <friction>
            <ode>
              <mu>1</mu>
              <mu2>1</mu2>
            </ode>
          </friction>
        </surface>
      </collision>
      <collision name='tilt_mechanism_fixed_joint_lump__camera_module_collision_1'>
        <pose>0.0145 0.00035 0 0 0 -1.5708</pose>
        <geometry>
          <box>
            <size>0.02375 0.0124 0.02375</size>
          </box>
        </geometry>
      </collision>
      <visual name='tilt_mechanism_visual'>
        <pose>0 0 0 0 -0 0</pose>
        <geometry>
          <mesh>
            <scale>1 1 1</scale>
            <uri>model://alex/meshes/tilt_asm_dessimate.dae</uri>
          </mesh>
        </geometry>
      </visual>
      <visual name='tilt_mechanism_fixed_joint_lump__camera_module_visual_1'>
        <pose>0.0176 0.00035 0 0 0 -1.5708</pose>
        <geometry>
          <mesh>
            <scale>1 1 1</scale>
            <uri>model://alex/meshes/camera_asm_2_dessimate.dae</uri>
          </mesh>
        </geometry>
      </visual>
      <visual name='tilt_mechanism_fixed_joint_lump__camera_sensor_visual_2'>
        <pose>0.019 0.00035 0 3.14159 -0 0</pose>
        <geometry>
          <box>
            <size>0.001 0.001 0.001</size>
          </box>
        </geometry>
      </visual>
      <velocity_decay/>
      <gravity>1</gravity>
      <velocity_decay/>
      <sensor name='camera1' type='camera'>
        <update_rate>30</update_rate>
        <camera name='pan_tilt_camera'>
          <horizontal_fov>1.88496</horizontal_fov>
          <image>
            <width>640</width>
            <height>480</height>
            <format>R8G8B8</format>
          </image>
          <clip>
            <near>0.02</near>
            <far>300</far>
          </clip>
          <noise>
            <type>gaussian</type>
            <mean>0</mean>
            <stddev>0.007</stddev>
          </noise>
        </camera>
        <plugin name='camera_controller' filename='libgazebo_ros_camera.so'>
          <alwaysOn>1</alwaysOn>
          <updateRate>0.0</updateRate>
          <cameraName>alex/camera1</cameraName>
          <imageTopicName>image_raw</imageTopicName>
          <cameraInfoTopicName>camera_info</cameraInfoTopicName>
          <frameName>camera_sensor</frameName>
          <hackBaseline>0.07</hackBaseline>
          <distortionK1>0.0</distortionK1>
          <distortionK2>0.0</distortionK2>
          <distortionK3>0.0</distortionK3>
          <distortionT1>0.0</distortionT1>
          <distortionT2>0.0</distortionT2>
        </plugin>
        <pose>0.019 0.00035 0 3.14159 -0 0</pose>
      </sensor>
    </link>
    <joint name='baselink_left_wheel_joint' type='revolute'>
      <pose relative_to='base_link'>0 0.0805 0 -1.5708 0 0</pose>
      <parent>base_link</parent>
      <child>left_wheel</child>
      <axis>
        <xyz>0 0 1</xyz>
        <limit>
          <lower>-1e+16</lower>
          <upper>1e+16</upper>
        </limit>
        <dynamics>
          <spring_reference>0</spring_reference>
          <spring_stiffness>0</spring_stiffness>
        </dynamics>
      </axis>
    </joint>
    <link name='left_wheel'>
      <pose relative_to='baselink_left_wheel_joint'>0 0 0 0 -0 0</pose>
      <inertial>
        <pose>0 0 0 0 -0 0</pose>
        <mass>0.01</mass>
        <inertia>
          <ixx>4.21646e-06</ixx>
          <ixy>0</ixy>
          <ixz>0</ixz>
          <iyy>4.21646e-06</iyy>
          <iyz>0</iyz>
          <izz>0.000457031</izz>
        </inertia>
      </inertial>
      <collision name='left_wheel_collision'>
        <pose>0 0 0 0 -0 0</pose>
        <geometry>
          <cylinder>
            <length>0.029</length>
            <radius>0.0375</radius>
          </cylinder>
        </geometry>
        <surface>
          <contact>
            <ode>
              <kp>500</kp>
              <kd>500</kd>
            </ode>
          </contact>
          <friction>
            <ode>
              <mu>10</mu>
              <mu2>10</mu2>
            </ode>
          </friction>
        </surface>
      </collision>
      <visual name='left_wheel_visual'>
        <pose>0 0 0 3.14159 0 3.14159</pose>
        <geometry>
          <mesh>
            <scale>1 1 1</scale>
            <uri>model://alex/meshes/wheel_asm_decimate_3.dae</uri>
          </mesh>
        </geometry>
      </visual>
      <gravity>1</gravity>
      <velocity_decay/>
    </link>
    <joint name='baselink_right_wheel_joint' type='revolute'>
      <pose relative_to='base_link'>0 -0.0805 0 -1.5708 0 0</pose>
      <parent>base_link</parent>
      <child>right_wheel</child>
      <axis>
        <xyz>0 0 1</xyz>
        <limit>
          <lower>-1e+16</lower>
          <upper>1e+16</upper>
        </limit>
        <dynamics>
          <spring_reference>0</spring_reference>
          <spring_stiffness>0</spring_stiffness>
        </dynamics>
      </axis>
    </joint>
    <link name='right_wheel'>
      <pose relative_to='baselink_right_wheel_joint'>0 0 0 0 -0 0</pose>
      <inertial>
        <pose>0 0 0 0 -0 0</pose>
        <mass>0.01</mass>
        <inertia>
          <ixx>4.21646e-06</ixx>
          <ixy>0</ixy>
          <ixz>0</ixz>
          <iyy>4.21646e-06</iyy>
          <iyz>0</iyz>
          <izz>0.000457031</izz>
        </inertia>
      </inertial>
      <collision name='right_wheel_collision'>
        <pose>0 0 0 0 -0 0</pose>
        <geometry>
          <cylinder>
            <length>0.029</length>
            <radius>0.0375</radius>
          </cylinder>
        </geometry>
        <surface>
          <contact>
            <ode>
              <kp>500</kp>
              <kd>500</kd>
            </ode>
          </contact>
          <friction>
            <ode>
              <mu>10</mu>
              <mu2>10</mu2>
            </ode>
          </friction>
        </surface>
      </collision>
      <visual name='right_wheel_visual'>
        <pose>0 0 0 0 -0 0</pose>
        <geometry>
          <mesh>
            <scale>1 1 1</scale>
            <uri>model://alex/meshes/wheel_asm_decimate_3.dae</uri>
          </mesh>
        </geometry>
      </visual>
      <gravity>1</gravity>
      <velocity_decay/>
    </link>
    <static>0</static>
    <plugin name='differential_drive_controller' filename='libgazebo_ros_diff_drive.so'>
      <legacyMode>0</legacyMode>
      <alwaysOn>1</alwaysOn>
      <updateRate>20</updateRate>
      <leftJoint>baselink_left_wheel_joint</leftJoint>
      <rightJoint>baselink_right_wheel_joint</rightJoint>
      <wheelSeparation>0.175</wheelSeparation>
      <wheelDiameter>0.075</wheelDiameter>
      <torque>0.01</torque>
      <commandTopic>cmd_vel</commandTopic>
      <odometryTopic>odom</odometryTopic>
      <odometryFrame>odom</odometryFrame>
      <robotBaseFrame>base_link</robotBaseFrame>
    </plugin>
    <plugin name='gazebo_ros_control' filename='libgazebo_ros_control.so'>
      <robotNamespace>/alex</robotNamespace>
    </plugin>
  </model>
</sdf>
