<?xml version="1.0" ?>
<!-- =================================================================================== -->
<!-- |    This document was autogenerated by xacro from robots/alex.urdf.xacro         | -->
<!-- |    EDITING THIS FILE BY HAND IS NOT RECOMMENDED                                 | -->
<!-- =================================================================================== -->
<robot name="alex">
  <material name="grey">
    <color rgba="0.75 0.75 0.75 1.0"/>
  </material>
  <material name="red">
    <color rgba="0.8 0 0 1"/>
  </material>
  <material name="black">
    <color rgba="1.0 1.0 1.0 1"/>
  </material>
  <material name="pi-top_green">
    <color rgba="0 0.7 0.64 1"/>
  </material>
  <!-- Gazebo parameters -->
  <gazebo>
    <plugin filename="libgazebo_ros_diff_drive.so" name="differential_drive_controller">
      <legacyMode>false</legacyMode>
      <alwaysOn>true</alwaysOn>
      <updateRate>20</updateRate>
      <leftJoint>baselink_left_wheel_joint</leftJoint>
      <rightJoint>baselink_right_wheel_joint</rightJoint>
      <wheelSeparation>0.175</wheelSeparation>
      <wheelDiameter>0.075</wheelDiameter>
      <torque>0.01</torque>
      <commandTopic>cmd_vel</commandTopic>
      <odometryTopic>odom</odometryTopic>
      <odometryFrame>odom</odometryFrame>
      <robotBaseFrame>base_link</robotBaseFrame>
    </plugin>
    <plugin filename="libgazebo_ros_control.so" name="gazebo_ros_control">
      <robotNamespace>/alex</robotNamespace>
    </plugin>
  </gazebo>
  <!-- * * * * * * * * * -->
  <!-- * * * * * * * * * -->
  <!-- * * * * * * * * * -->
  <!-- * * * * * * * * * -->
  <!-- * * * * * * * * * -->
  <!-- * * * * * * * * * -->
  <!-- * * * * * * * * * -->
  <!-- * * * * * * * * * -->
  <gazebo reference="camera_sensor">
    <sensor name="camera1" type="camera">
      <update_rate>30.0</update_rate>
      <camera name="pan_tilt_camera">
        <horizontal_fov>1.8849555921538759</horizontal_fov>
        <image>
          <width>640</width>
          <height>480</height>
          <format>R8G8B8</format>
        </image>
        <clip>
          <near>0.02</near>
          <far>300</far>
        </clip>
        <noise>
          <type>gaussian</type>
          <!-- Noise is sampled independently per pixel on each frame.
                    That pixel's noise value is added to each of its color
                    channels, which at that point lie in the range [0,1]. -->
          <mean>0.0</mean>
          <stddev>0.007</stddev>
        </noise>
      </camera>
      <plugin filename="libgazebo_ros_camera.so" name="camera_controller">
        <alwaysOn>true</alwaysOn>
        <updateRate>0.0</updateRate>
        <cameraName>alex/camera1</cameraName>
        <imageTopicName>image_raw</imageTopicName>
        <cameraInfoTopicName>camera_info</cameraInfoTopicName>
        <frameName>camera_sensor</frameName>
        <hackBaseline>0.07</hackBaseline>
        <distortionK1>0.0</distortionK1>
        <distortionK2>0.0</distortionK2>
        <distortionK3>0.0</distortionK3>
        <distortionT1>0.0</distortionT1>
        <distortionT2>0.0</distortionT2>
      </plugin>
    </sensor>
  </gazebo>
  <!--    <xacro:macro name="camera_sensor_joint_origin">-->
  <!--        <origin xyz="0 0.0014 0" rpy="${-pi/2} ${pi} 0"/>-->
  <!--    </xacro:macro>-->
  <!-- * * * * * * * * * -->
  <!-- * * * * * * * * * -->
  <!-- Model Definitions -->
  <link name="base_link">
    <pose>0 0 0.0375 0 0 0</pose>
  </link>
  <link name="chassis">
    <inertial>
      <origin rpy="0 0 0" xyz="0 -0.046975 0"/>
      <mass value="0.65"/>
      <inertia ixx="0.004314754166666667" ixy="0.0" ixz="0.0" iyy="0.006123" iyz="0.0" izz="0.0021853541666666666"/>
    </inertial>
    <visual>
      <origin rpy="0 0 0" xyz="0 0 0"/>
      <geometry>
        <!--                <box size="${chassis_width_x} ${chassis_depth_y} ${chassis_height_z}"/>-->
        <mesh filename="model://alex/meshes/chassis_asm_dessimate.dae"/>
      </geometry>
      <material name="black"/>
    </visual>
    <collision>
      <origin rpy="0 0 0" xyz="0 -0.046975 0"/>
      <geometry>
        <box size="0.192 0.059 0.276"/>
      </geometry>
    </collision>
  </link>
  <joint name="baselink_chassis_joint" type="fixed">
    <parent link="base_link"/>
    <child link="chassis"/>
    <origin rpy="1.5707963267948966 0 -1.5707963267948966" xyz="-0.068 0 0.056475"/>
  </joint>
  <gazebo reference="chassis">
    <kp>10000.0</kp>
    <kd>10000.0</kd>
    <mu1>1.0</mu1>
    <mu2>1.0</mu2>
  </gazebo>
  <link name="ep">
    <inertial>
      <origin rpy="0 0 0" xyz="0 -0.0085 0"/>
      <mass value="0.05"/>
      <inertia ixx="7.616666666666668e-05" ixy="0.0" ixz="0.0" iyy="0.00011774270833333335" iyz="0.0" izz="4.4276041666666666e-05"/>
    </inertial>
    <visual>
      <origin rpy="0 0 0" xyz="0 0 0"/>
      <geometry>
        <box size="0.1015 0.018 0.134"/>
        <!--                <mesh filename="${ep_mesh_path}"/>-->
      </geometry>
      <material name="black"/>
    </visual>
    <collision>
      <origin rpy="0 0 0" xyz="0 -0.0085 0"/>
      <geometry>
        <box size="0.1015 0.018 0.134"/>
      </geometry>
    </collision>
  </link>
  <joint name="chassis_ep_joint" type="fixed">
    <parent link="chassis"/>
    <child link="ep"/>
    <!--    	<xacro:ep_joint_origin/>-->
  </joint>
  <gazebo reference="ep">
    <kp>10000.0</kp>
    <kd>10000.0</kd>
    <mu1>1.0</mu1>
    <mu2>1.0</mu2>
  </gazebo>
  <link name="pt4">
    <inertial>
      <origin rpy="0 0 0" xyz="0 0.017 0"/>
      <mass value="0.39"/>
      <inertia ixx="0.0006038500000000001" ixy="0.0" ixz="0.0" iyy="0.0008880381250000001" iyz="0.0" izz="0.00035932812500000006"/>
    </inertial>
    <visual>
      <origin rpy="0 0 0" xyz="0 0 0"/>
      <geometry>
        <box size="0.0995 0.034 0.132"/>
        <!--                <mesh filename="${pt4_mesh_path}"/>-->
      </geometry>
      <material name="black"/>
    </visual>
    <collision>
      <origin rpy="0 0 0" xyz="0 0.017 0"/>
      <geometry>
        <box size="0.0995 0.034 0.132"/>
      </geometry>
    </collision>
  </link>
  <joint name="chassis_pt4_joint" type="fixed">
    <parent link="chassis"/>
    <child link="pt4"/>
    <!--    	<xacro:pt4_joint_origin/>-->
  </joint>
  <gazebo reference="pt4">
    <kp>10000.0</kp>
    <kd>10000.0</kd>
    <mu1>1.0</mu1>
    <mu2>1.0</mu2>
  </gazebo>
  <link name="right_wheel">
    <inertial>
      <origin rpy="0 0 0" xyz="0 0 0"/>
      <mass value="0.01"/>
      <inertia ixx="4.2164583333333334e-06" ixy="0.0" ixz="0.0" iyy="4.2164583333333334e-06" iyz="0.0" izz="0.00045703124999999997"/>
    </inertial>
    <visual>
      <origin rpy="0 0 0" xyz="0 0 0"/>
      <geometry>
        <mesh filename="model://alex/meshes/wheel_asm_decimate_3.dae"/>
        <!--                <cylinder radius="${wheel_radius}" length="${wheel_width}"/>-->
      </geometry>
      <material name="black"/>
    </visual>
    <collision>
      <origin rpy="0 0 0" xyz="0 0 0"/>
      <geometry>
        <cylinder length="0.029" radius="0.0375"/>
      </geometry>
    </collision>
  </link>
  <joint name="baselink_right_wheel_joint" type="continuous">
    <parent link="base_link"/>
    <child link="right_wheel"/>
    <origin rpy="-1.5707963267948966 0 0" xyz="0 -0.0805 0"/>
    <limit effort="0.1" velocity="0.45"/>
    <axis rpy="0 0 0" xyz="0 0 1"/>
    <joint_properties damping="1.0" friction="1.0"/>
  </joint>
  <link name="left_wheel">
    <inertial>
      <origin rpy="0 0 0" xyz="0 0 0"/>
      <mass value="0.01"/>
      <inertia ixx="4.2164583333333334e-06" ixy="0.0" ixz="0.0" iyy="4.2164583333333334e-06" iyz="0.0" izz="0.00045703124999999997"/>
    </inertial>
    <visual>
      <origin rpy="0 3.141592653589793 0" xyz="0 0 0"/>
      <geometry>
        <mesh filename="model://alex/meshes/wheel_asm_decimate_3.dae"/>
        <!--                <cylinder radius="${wheel_radius}" length="${wheel_width}"/>-->
      </geometry>
      <material name="black"/>
    </visual>
    <collision>
      <origin rpy="0 0 0" xyz="0 0 0"/>
      <geometry>
        <cylinder length="0.029" radius="0.0375"/>
      </geometry>
    </collision>
  </link>
  <joint name="baselink_left_wheel_joint" type="continuous">
    <parent link="base_link"/>
    <child link="left_wheel"/>
    <origin rpy="-1.5707963267948966 0 0" xyz="0 0.0805 0"/>
    <limit effort="0.1" velocity="0.45"/>
    <axis rpy="0 0 0" xyz="0 0 1"/>
    <joint_properties damping="1.0" friction="1.0"/>
  </joint>
  <link name="castor">
    <inertial>
      <origin rpy="0 0 0" xyz="0 0 -0.0125"/>
      <mass value="0.001"/>
      <inertia ixx="1.1769333333333332e-07" ixy="0.0" ixz="0.0" iyy="1.1769333333333332e-07" iyz="0.0" izz="1.3121999999999998e-07"/>
    </inertial>
    <visual>
      <origin rpy="1.5707963267948966 0 -1.5707963267948966" xyz="0.08 0 0.058515"/>
      <geometry>
        <mesh filename="model://alex/meshes/castor_asm_3_dessimate.dae"/>
      </geometry>
    </visual>
    <collision>
      <origin rpy="0 0 0" xyz="0 0 -0.0125"/>
      <geometry>
        <cylinder length="0.025" radius="0.0162"/>
      </geometry>
    </collision>
  </link>
  <joint name="baselink_castor_joint" type="continuous">
    <parent link="base_link"/>
    <child link="castor"/>
    <origin rpy="0 0 0" xyz="-0.148 0 -0.00204"/>
    <limit effort="1.0" velocity="0.45"/>
    <axis rpy="0 0 0" xyz="0 0 1"/>
    <joint_properties damping="1.0" friction="1.0"/>
  </joint>
  <gazebo reference="castor">
    <kp>10000.0</kp>
    <kd>10000.0</kd>
    <mu1>10.0</mu1>
    <mu2>10.0</mu2>
  </gazebo>
  <link name="castor_wheel">
    <inertial>
      <origin rpy="0 0 0" xyz="0 0 0"/>
      <mass value="0.001"/>
      <inertia ixx="5.658333333333334e-08" ixy="0.0" ixz="0.0" iyy="5.658333333333334e-08" iyz="0.0" izz="7.812500000000002e-08"/>
    </inertial>
    <collision>
      <origin rpy="0 0 0" xyz="0 0 0"/>
      <geometry>
        <cylinder length="0.0145" radius="0.0125"/>
      </geometry>
    </collision>
  </link>
  <joint name="castor_castorwheel_joint" type="continuous">
    <parent link="castor"/>
    <child link="castor_wheel"/>
    <origin rpy="-1.5707963267948966 0 0" xyz="-0.016 0 -0.0205"/>
    <limit effort="1.0" velocity="0.45"/>
    <axis rpy="0 0 0" xyz="0 0 1"/>
    <joint_properties damping="1.0" friction="1.0"/>
  </joint>
  <link name="pan_mechanism">
    <inertial>
      <origin rpy="0 0 0" xyz="0 0 0"/>
      <mass value="0.005"/>
      <inertia ixx="1.5776041666666668e-06" ixy="0.0" ixz="0.0" iyy="1.066666666666667e-06" iyz="0.0" izz="7.242708333333334e-07"/>
    </inertial>
    <visual>
      <!--            <xacro:pan_mechanism_origin/>-->
      <origin rpy="0 0 0" xyz="0 0 0"/>
      <geometry>
        <!--                <box size="${pan_mechanism_width_x} ${pan_mechanism_depth_y} ${pan_mechanism_height_z}"/>-->
        <mesh filename="model://alex/meshes/pan_asm_2_dessimate_2.dae"/>
      </geometry>
      <material name="black"/>
    </visual>
    <collision>
      <origin rpy="0 0 0" xyz="0 0 0"/>
      <geometry>
        <box size="0.016 0.0385 0.048"/>
      </geometry>
    </collision>
  </link>
  <joint name="pan_mechanism_joint" type="revolute">
    <parent link="chassis"/>
    <child link="pan_mechanism"/>
    <origin rpy="3.141592653589793 -1.5707963267948966 0" xyz="0 -0.0372805 -0.142268"/>
    <limit effort="1.0" lower="-1.5707963267948966" upper="1.5707963267948966" velocity="1.7453292519943295"/>
    <axis rpy="0 0 0" xyz="0 1 0"/>
    <joint_properties damping="1.0" friction="1.0"/>
  </joint>
  <link name="tilt_mechanism">
    <inertial>
      <origin rpy="0 0 0" xyz="0 0 0"/>
      <mass value="0.005"/>
      <inertia ixx="1.5776041666666668e-06" ixy="0.0" ixz="0.0" iyy="1.066666666666667e-06" iyz="0.0" izz="7.242708333333334e-07"/>
    </inertial>
    <visual>
      <!--            <xacro:tilt_mechanism_origin/>-->
      <origin rpy="0 0 0" xyz="0 0 0"/>
      <geometry>
        <!--                <box size="${tilt_mechanism_width_x} ${tilt_mechanism_depth_y} ${tilt_mechanism_height_z}"/>-->
        <mesh filename="model://alex/meshes/tilt_asm_dessimate.dae"/>
      </geometry>
      <material name="black"/>
    </visual>
    <collision>
      <origin rpy="0 0 0" xyz="0 0 0"/>
      <geometry>
        <box size="0.016 0.0385 0.048"/>
      </geometry>
    </collision>
  </link>
  <joint name="tilt_mechanism_joint" type="revolute">
    <parent link="pan_mechanism"/>
    <child link="tilt_mechanism"/>
    <origin rpy="1.5707963267948966 0 3.141592653589793" xyz="0 -0.04825 -0.000526152"/>
    <limit effort="1.0" lower="-1.5707963267948966" upper="1.5707963267948966" velocity="1.7453292519943295"/>
    <axis rpy="0 0 0" xyz="0 1 0"/>
    <joint_properties damping="1.0" friction="1.0"/>
  </joint>
  <gazebo reference="left_wheel">
    <kp>500.0</kp>
    <kd>500.0</kd>
    <mu1>10.0</mu1>
    <mu2>10.0</mu2>
  </gazebo>
  <gazebo reference="right_wheel">
    <kp>500.0</kp>
    <kd>500.0</kd>
    <mu1>10.0</mu1>
    <mu2>10.0</mu2>
  </gazebo>
  <gazebo reference="castor_wheel">
    <kp>1000.0</kp>
    <kd>1000.0</kd>
    <mu1>10.0</mu1>
    <mu2>10.0</mu2>
  </gazebo>
  <gazebo reference="pan_mechanism">
    <kp>10000.0</kp>
    <kd>10000.0</kd>
    <mu1>1.0</mu1>
    <mu2>1.0</mu2>
  </gazebo>
  <gazebo reference="tilt_mechanism">
    <kp>10000.0</kp>
    <kd>10000.0</kd>
    <mu1>1.0</mu1>
    <mu2>1.0</mu2>
  </gazebo>
  <transmission name="pan_transmission">
    <type>transmission_interface/SimpleTransmission</type>
    <joint name="pan_mechanism_joint">
      <hardwareInterface>hardware_interface/PositionJointInterface</hardwareInterface>
    </joint>
    <actuator name="pan_servo_actuator">
      <hardwareInterface>hardware_interface/PositionJointInterface</hardwareInterface>
      <mechanicalReduction>1</mechanicalReduction>
    </actuator>
  </transmission>
  <transmission name="tilt_transmission">
    <type>transmission_interface/SimpleTransmission</type>
    <joint name="tilt_mechanism_joint">
      <hardwareInterface>hardware_interface/PositionJointInterface</hardwareInterface>
    </joint>
    <actuator name="tilt_servo_actuator">
      <hardwareInterface>hardware_interface/PositionJointInterface</hardwareInterface>
      <mechanicalReduction>1</mechanicalReduction>
    </actuator>
  </transmission>
  <link name="camera_module">
    <inertial>
      <origin rpy="0 0 0" xyz="0 -0.0031 0"/>
      <mass value="0.005"/>
      <inertia ixx="2.9909270833333334e-07" ixy="0.0" ixz="0.0" iyy="4.7005208333333334e-07" iyz="0.0" izz="2.9909270833333334e-07"/>
    </inertial>
    <visual>
      <!--            <xacro:camera_module_box_origin/>-->
      <origin rpy="0 0 0" xyz="0 0 0"/>
      <geometry>
        <!--                <box size="${camera_module_width_x} ${camera_module_depth_y} ${camera_module_height_z}"/>-->
        <mesh filename="model://alex/meshes/camera_asm_2_dessimate.dae"/>
      </geometry>
      <material name="black"/>
    </visual>
    <collision>
      <origin rpy="0 0 0" xyz="0 -0.0031 0"/>
      <geometry>
        <box size="0.02375 0.0124 0.02375"/>
      </geometry>
    </collision>
  </link>
  <joint name="camera_module_joint" type="fixed">
    <parent link="tilt_mechanism"/>
    <child link="camera_module"/>
    <origin rpy="0 0 -1.5707963267948966" xyz="0.0176 0.00035 0"/>
  </joint>
  <link name="camera_sensor">
    <visual>
      <origin rpy="0 0 0" xyz="0 0 0"/>
      <geometry>
        <box size="0.001 0.001 0.001"/>
      </geometry>
      <material name="red"/>
    </visual>
  </link>
  <joint name="camera_sensor_joint" type="fixed">
    <parent link="camera_module"/>
    <child link="camera_sensor"/>
    <origin rpy="3.141592653589793 0 1.5707963267948966" xyz="0 0.0014 0"/>
  </joint>
  <link name="imu_link">
    <visual>
      <origin rpy="0 0 0" xyz="0 0 0"/>
      <geometry>
        <box size="0.001 0.001 0.001"/>
      </geometry>
      <material name="red"/>
    </visual>
  </link>
  <joint name="ep_imu_joint" type="fixed">
    <parent link="ep"/>
    <child link="imu_link"/>
    <origin rpy="0 0 0" xyz="0 -0.0085 0"/>
  </joint>
  <gazebo reference="imu_link">
    <gravity>true</gravity>
    <sensor name="imu_sensor" type="imu">
      <always_on>true</always_on>
      <update_rate>100</update_rate>
      <visualize>true</visualize>
      <topic>__default_topic__</topic>
      <plugin filename="libgazebo_ros_imu_sensor.so" name="imu_plugin">
        <topicName>imu</topicName>
        <bodyName>imu_link</bodyName>
        <updateRateHZ>10.0</updateRateHZ>
        <gaussianNoise>0.0</gaussianNoise>
        <xyzOffset>0 0 0</xyzOffset>
        <rpyOffset>0 0 0</rpyOffset>
        <frameName>imu_link</frameName>
        <initialOrientationAsReference>false</initialOrientationAsReference>
      </plugin>
      <pose>0 0 0 0 0 0</pose>
    </sensor>
  </gazebo>
</robot>

